[2025-08-27T10:09:01.541+0000] {local_task_job_runner.py:123} INFO - ::group::Pre task execution logs
[2025-08-27T10:09:01.548+0000] {taskinstance.py:2612} INFO - Dependencies all met for dep_context=non-requeueable deps ti=<TaskInstance: unemployment_etl_dag.merge_cz_files manual__2025-08-27T10:08:29.205342+00:00 [queued]>
[2025-08-27T10:09:01.552+0000] {taskinstance.py:2612} INFO - Dependencies all met for dep_context=requeueable deps ti=<TaskInstance: unemployment_etl_dag.merge_cz_files manual__2025-08-27T10:08:29.205342+00:00 [queued]>
[2025-08-27T10:09:01.552+0000] {taskinstance.py:2865} INFO - Starting attempt 1 of 1
[2025-08-27T10:09:01.556+0000] {taskinstance.py:2888} INFO - Executing <Task(PythonOperator): merge_cz_files> on 2025-08-27 10:08:29.205342+00:00
[2025-08-27T10:09:01.560+0000] {warnings.py:112} WARNING - /home/***/.local/lib/python3.12/site-packages/***/task/task_runner/standard_task_runner.py:70: DeprecationWarning: This process (pid=1772) is multi-threaded, use of fork() may lead to deadlocks in the child.
  pid = os.fork()

[2025-08-27T10:09:01.561+0000] {standard_task_runner.py:72} INFO - Started process 1776 to run task
[2025-08-27T10:09:01.561+0000] {standard_task_runner.py:104} INFO - Running: ['***', 'tasks', 'run', 'unemployment_etl_dag', 'merge_cz_files', 'manual__2025-08-27T10:08:29.205342+00:00', '--job-id', '14', '--raw', '--subdir', 'DAGS_FOLDER/unemployment_etl_dag.py', '--cfg-path', '/tmp/tmp_k9smzoz']
[2025-08-27T10:09:01.562+0000] {standard_task_runner.py:105} INFO - Job 14: Subtask merge_cz_files
[2025-08-27T10:09:01.585+0000] {task_command.py:467} INFO - Running <TaskInstance: unemployment_etl_dag.merge_cz_files manual__2025-08-27T10:08:29.205342+00:00 [running]> on host 6c81a3d5d2a8
[2025-08-27T10:09:01.615+0000] {taskinstance.py:3131} INFO - Exporting env vars: AIRFLOW_CTX_DAG_OWNER='***' AIRFLOW_CTX_DAG_ID='unemployment_etl_dag' AIRFLOW_CTX_TASK_ID='merge_cz_files' AIRFLOW_CTX_EXECUTION_DATE='2025-08-27T10:08:29.205342+00:00' AIRFLOW_CTX_TRY_NUMBER='1' AIRFLOW_CTX_DAG_RUN_ID='manual__2025-08-27T10:08:29.205342+00:00'
[2025-08-27T10:09:01.615+0000] {logging_mixin.py:190} INFO - Task instance is in running state
[2025-08-27T10:09:01.615+0000] {logging_mixin.py:190} INFO -  Previous state of the Task instance: queued
[2025-08-27T10:09:01.615+0000] {logging_mixin.py:190} INFO - Current task name:merge_cz_files state:running start_date:2025-08-27 10:09:01.549257+00:00
[2025-08-27T10:09:01.616+0000] {logging_mixin.py:190} INFO - Dag name:unemployment_etl_dag and current dag run status:running
[2025-08-27T10:09:01.616+0000] {taskinstance.py:731} INFO - ::endgroup::
[2025-08-27T10:09:01.629+0000] {taskinstance.py:3310} ERROR - Task failed with exception
Traceback (most recent call last):
  File "/home/airflow/.local/lib/python3.12/site-packages/airflow/models/taskinstance.py", line 767, in _execute_task
    result = _execute_callable(context=context, **execute_callable_kwargs)
             ^^^^^^^^^^^^^^^^^^^^^^^^^^^^^^^^^^^^^^^^^^^^^^^^^^^^^^^^^^^^^
  File "/home/airflow/.local/lib/python3.12/site-packages/airflow/models/taskinstance.py", line 733, in _execute_callable
    return ExecutionCallableRunner(
           ^^^^^^^^^^^^^^^^^^^^^^^^
  File "/home/airflow/.local/lib/python3.12/site-packages/airflow/utils/operator_helpers.py", line 252, in run
    return self.func(*args, **kwargs)
           ^^^^^^^^^^^^^^^^^^^^^^^^^^
  File "/home/airflow/.local/lib/python3.12/site-packages/airflow/models/baseoperator.py", line 406, in wrapper
    return func(self, *args, **kwargs)
           ^^^^^^^^^^^^^^^^^^^^^^^^^^^
  File "/home/airflow/.local/lib/python3.12/site-packages/airflow/operators/python.py", line 238, in execute
    return_value = self.execute_callable()
                   ^^^^^^^^^^^^^^^^^^^^^^^
  File "/home/airflow/.local/lib/python3.12/site-packages/airflow/operators/python.py", line 256, in execute_callable
    return runner.run(*self.op_args, **self.op_kwargs)
           ^^^^^^^^^^^^^^^^^^^^^^^^^^^^^^^^^^^^^^^^^^^
  File "/home/airflow/.local/lib/python3.12/site-packages/airflow/utils/operator_helpers.py", line 252, in run
    return self.func(*args, **kwargs)
           ^^^^^^^^^^^^^^^^^^^^^^^^^^
  File "/opt/airflow/dags/get_data.py", line 147, in merge_country_files
    merged_df = pd.merge(
                ^^^^^^^^^
  File "/home/airflow/.local/lib/python3.12/site-packages/pandas/core/reshape/merge.py", line 183, in merge
    return op.get_result(copy=copy)
           ^^^^^^^^^^^^^^^^^^^^^^^^
  File "/home/airflow/.local/lib/python3.12/site-packages/pandas/core/reshape/merge.py", line 885, in get_result
    result = self._reindex_and_concat(
             ^^^^^^^^^^^^^^^^^^^^^^^^^
  File "/home/airflow/.local/lib/python3.12/site-packages/pandas/core/reshape/merge.py", line 837, in _reindex_and_concat
    llabels, rlabels = _items_overlap_with_suffix(
                       ^^^^^^^^^^^^^^^^^^^^^^^^^^^
  File "/home/airflow/.local/lib/python3.12/site-packages/pandas/core/reshape/merge.py", line 2697, in _items_overlap_with_suffix
    raise MergeError(
pandas.errors.MergeError: Passing 'suffixes' which cause duplicate columns {'unit_x', 'indicator.value_x', 'country.id_x', 'indicator.id_x', 'obs_status_x', 'decimal_x', 'countryiso3code_x'} is not allowed.
[2025-08-27T10:09:01.633+0000] {logging_mixin.py:190} INFO - Task instance in failure state
[2025-08-27T10:09:01.633+0000] {logging_mixin.py:190} INFO - Task start:2025-08-27 10:09:01.549257+00:00 end:2025-08-27 10:09:01.632957+00:00 duration:0.0837
[2025-08-27T10:09:01.633+0000] {logging_mixin.py:190} INFO - Task:<Task(PythonOperator): merge_cz_files> dag:<DAG: unemployment_etl_dag> dagrun:<DagRun unemployment_etl_dag @ 2025-08-27 10:08:29.205342+00:00: manual__2025-08-27T10:08:29.205342+00:00, state:running, queued_at: 2025-08-27 10:08:29.214796+00:00. externally triggered: True>
[2025-08-27T10:09:01.633+0000] {logging_mixin.py:190} INFO - Failure caused by Passing 'suffixes' which cause duplicate columns {'unit_x', 'indicator.value_x', 'country.id_x', 'indicator.id_x', 'obs_status_x', 'decimal_x', 'countryiso3code_x'} is not allowed.
[2025-08-27T10:09:01.633+0000] {taskinstance.py:1225} INFO - Marking task as FAILED. dag_id=unemployment_etl_dag, task_id=merge_cz_files, run_id=manual__2025-08-27T10:08:29.205342+00:00, execution_date=20250827T100829, start_date=20250827T100901, end_date=20250827T100901
[2025-08-27T10:09:01.637+0000] {taskinstance.py:340} INFO - ::group::Post task execution logs
[2025-08-27T10:09:01.637+0000] {standard_task_runner.py:124} ERROR - Failed to execute job 14 for task merge_cz_files (Passing 'suffixes' which cause duplicate columns {'unit_x', 'indicator.value_x', 'country.id_x', 'indicator.id_x', 'obs_status_x', 'decimal_x', 'countryiso3code_x'} is not allowed.; 1776)
Traceback (most recent call last):
  File "/home/airflow/.local/lib/python3.12/site-packages/airflow/task/task_runner/standard_task_runner.py", line 117, in _start_by_fork
    ret = args.func(args, dag=self.dag)
          ^^^^^^^^^^^^^^^^^^^^^^^^^^^^^
  File "/home/airflow/.local/lib/python3.12/site-packages/airflow/cli/cli_config.py", line 49, in command
    return func(*args, **kwargs)
           ^^^^^^^^^^^^^^^^^^^^^
  File "/home/airflow/.local/lib/python3.12/site-packages/airflow/utils/cli.py", line 115, in wrapper
    return f(*args, **kwargs)
           ^^^^^^^^^^^^^^^^^^
  File "/home/airflow/.local/lib/python3.12/site-packages/airflow/cli/commands/task_command.py", line 483, in task_run
    task_return_code = _run_task_by_selected_method(args, _dag, ti)
                       ^^^^^^^^^^^^^^^^^^^^^^^^^^^^^^^^^^^^^^^^^^^^
  File "/home/airflow/.local/lib/python3.12/site-packages/airflow/cli/commands/task_command.py", line 256, in _run_task_by_selected_method
    return _run_raw_task(args, ti)
           ^^^^^^^^^^^^^^^^^^^^^^^
  File "/home/airflow/.local/lib/python3.12/site-packages/airflow/cli/commands/task_command.py", line 341, in _run_raw_task
    return ti._run_raw_task(
           ^^^^^^^^^^^^^^^^^
  File "/home/airflow/.local/lib/python3.12/site-packages/airflow/utils/session.py", line 97, in wrapper
    return func(*args, session=session, **kwargs)
           ^^^^^^^^^^^^^^^^^^^^^^^^^^^^^^^^^^^^^^
  File "/home/airflow/.local/lib/python3.12/site-packages/airflow/models/taskinstance.py", line 3004, in _run_raw_task
    return _run_raw_task(
           ^^^^^^^^^^^^^^
  File "/home/airflow/.local/lib/python3.12/site-packages/airflow/models/taskinstance.py", line 273, in _run_raw_task
    TaskInstance._execute_task_with_callbacks(
  File "/home/airflow/.local/lib/python3.12/site-packages/airflow/models/taskinstance.py", line 3158, in _execute_task_with_callbacks
    result = self._execute_task(context, task_orig)
             ^^^^^^^^^^^^^^^^^^^^^^^^^^^^^^^^^^^^^^
  File "/home/airflow/.local/lib/python3.12/site-packages/airflow/models/taskinstance.py", line 3182, in _execute_task
    return _execute_task(self, context, task_orig)
           ^^^^^^^^^^^^^^^^^^^^^^^^^^^^^^^^^^^^^^^
  File "/home/airflow/.local/lib/python3.12/site-packages/airflow/models/taskinstance.py", line 767, in _execute_task
    result = _execute_callable(context=context, **execute_callable_kwargs)
             ^^^^^^^^^^^^^^^^^^^^^^^^^^^^^^^^^^^^^^^^^^^^^^^^^^^^^^^^^^^^^
  File "/home/airflow/.local/lib/python3.12/site-packages/airflow/models/taskinstance.py", line 733, in _execute_callable
    return ExecutionCallableRunner(
           ^^^^^^^^^^^^^^^^^^^^^^^^
  File "/home/airflow/.local/lib/python3.12/site-packages/airflow/utils/operator_helpers.py", line 252, in run
    return self.func(*args, **kwargs)
           ^^^^^^^^^^^^^^^^^^^^^^^^^^
  File "/home/airflow/.local/lib/python3.12/site-packages/airflow/models/baseoperator.py", line 406, in wrapper
    return func(self, *args, **kwargs)
           ^^^^^^^^^^^^^^^^^^^^^^^^^^^
  File "/home/airflow/.local/lib/python3.12/site-packages/airflow/operators/python.py", line 238, in execute
    return_value = self.execute_callable()
                   ^^^^^^^^^^^^^^^^^^^^^^^
  File "/home/airflow/.local/lib/python3.12/site-packages/airflow/operators/python.py", line 256, in execute_callable
    return runner.run(*self.op_args, **self.op_kwargs)
           ^^^^^^^^^^^^^^^^^^^^^^^^^^^^^^^^^^^^^^^^^^^
  File "/home/airflow/.local/lib/python3.12/site-packages/airflow/utils/operator_helpers.py", line 252, in run
    return self.func(*args, **kwargs)
           ^^^^^^^^^^^^^^^^^^^^^^^^^^
  File "/opt/airflow/dags/get_data.py", line 147, in merge_country_files
    merged_df = pd.merge(
                ^^^^^^^^^
  File "/home/airflow/.local/lib/python3.12/site-packages/pandas/core/reshape/merge.py", line 183, in merge
    return op.get_result(copy=copy)
           ^^^^^^^^^^^^^^^^^^^^^^^^
  File "/home/airflow/.local/lib/python3.12/site-packages/pandas/core/reshape/merge.py", line 885, in get_result
    result = self._reindex_and_concat(
             ^^^^^^^^^^^^^^^^^^^^^^^^^
  File "/home/airflow/.local/lib/python3.12/site-packages/pandas/core/reshape/merge.py", line 837, in _reindex_and_concat
    llabels, rlabels = _items_overlap_with_suffix(
                       ^^^^^^^^^^^^^^^^^^^^^^^^^^^
  File "/home/airflow/.local/lib/python3.12/site-packages/pandas/core/reshape/merge.py", line 2697, in _items_overlap_with_suffix
    raise MergeError(
pandas.errors.MergeError: Passing 'suffixes' which cause duplicate columns {'unit_x', 'indicator.value_x', 'country.id_x', 'indicator.id_x', 'obs_status_x', 'decimal_x', 'countryiso3code_x'} is not allowed.
[2025-08-27T10:09:01.660+0000] {local_task_job_runner.py:266} INFO - Task exited with return code 1
[2025-08-27T10:09:01.667+0000] {taskinstance.py:3900} INFO - 0 downstream tasks scheduled from follow-on schedule check
[2025-08-27T10:09:01.668+0000] {local_task_job_runner.py:245} INFO - ::endgroup::
